Workbook
Name Slicer_Year: #N/A

Sheet README
A1: Title: | B1: Clean Energy Monitoring Dashboard
A2: Author: | B2: Your Name
A3: Date: | B3: 45717
A5: PROJECT OVERVIEW
A6: (3-4 sentences describing what this workbook does and why)
A8: DATA SOURCE
A9: Source: | B9: World Bank Open Data (data.worldbank.org)
A10: Indicators: | B10: EG.ELC.ACCS.ZS | EG.FEC.RNEW.ZS | EN.ATM.CO2E.PC | EG.USE.PCAP.KG.OE |
A11: Coverage: | B11: 217 Countries | Years 2010–2022
A13: COLUMN DICTIONARY
A14: Country_Name | B14: Full country name
A15: Country_Code | B15: SO 3-letter country code
A16: Year of observation (2010–2022)
A17: Electricity_Access | B17: % of population with access to electricity
A18: Renewable_Share | B18: % of total energy consumption from renewables
A19: CO2_Per_Capita | B19: CO2 emissions in metric tons per person
A20: EnergyUse_percapita | B20: Energy use in kg of oil equivalent per capita
A21: Population | B21: Total population
A22: CountryYear_Key | B22: Unique ID: CountryCode-Year (e.g. IND-2022)
A24: SHEET GUIDE
A25: Master_Data | B25: Full cleaned dataset (source of truth)
A26: Data_QA | B26: Quality checks on the master data
A27: Calculations | B27: Reusable metrics referenced by dashboard
A28: Pivot_1 | B28: Global trend by year (2010–2022)
A29: Pivot_2 | B29: Country averages (all years)
A30: Pivot_3 | B30: 2022 snapshot — all countries ranked
A31: Pivot_4 | B31: Regional/income group summary
A32: Pivot_5 | B32: High renewable vs low CO2 analysis
A33: Dashboard | B33: Executive summary with KPIs and charts
A34: Country Deep Dive | B34: Individual country profile (2022)

Sheet Pivot_1
B3: Values
A4: Row Labels | B4: Average of Electricity_Access | C4: Average of Renewable_Share | D4: Average of CO2_Per_Capita
A5: 2010 | B5: 79.624657 | C5: 30.412665 | D5: 5.0980592
A6: 2011 | B6: 80.415327 | C6: 30.19737 | D6: 5.1265334
A7: 2012 | B7: 81.120805 | C7: 30.107129 | D7: 5.4055041
A8: 2013 | B8: 81.712538 | C8: 30.30164 | D8: 4.9683704
A9: 2014 | B9: 82.440903 | C9: 30.111727 | D9: 4.7912869
A10: 2015 | B10: 83.015239 | C10: 29.915157 | D10: 4.7094414
A11: 2016 | B11: 84.094751 | C11: 29.706058 | D11: 4.6743718
A12: 2017 | B12: 84.853908 | C12: 29.541519 | D12: 4.6777511
A13: 2018 | B13: 85.483801 | C13: 29.56303 | D13: 4.710869
A14: 2019 | B14: 86.041377 | C14: 29.462191 | D14: 4.6834013
A15: 2020 | B15: 86.573835 | C15: 30.534853 | D15: 4.4007476
A16: 2021 | B16: 87.125169 | C16: 29.603382 | D16: 4.5807343
A17: 2022 | B17: 87.414054 | C17: 30.421739 | D17: 4.5508011
A18: Grand Total | B18: 83.83972 | C18: 29.970087 | D18: 4.7982978

Sheet Pivot_2
B3: Values
A4: Row Labels | B4: Average of Electricity_Access | C4: Average of Renewable_Share | D4: Average of CO2_Per_Capita
A5: South Sudan | B5: 5.1153846 | C5: 30.95
A6: Burundi | B6: 8.1923077 | C6: 88.315385 | D6: 0.051368073
A7: Chad | B7: 9.2230769 | C7: 73.615385 | D7: 0.11430001
A8: Malawi | B8: 11.384615 | C8: 76.2 | D8: 0.30385512
A9: Burkina Faso | B9: 16.646154 | C9: 76.376923 | D9: 0.21167789
A10: Niger | B10: 16.715385 | C10: 79.391667 | D10: 0.10450897
A11: Congo, Dem. Rep. | B11: 17.146154 | C11: 95.833333 | D11: 0.045411355
A12: Liberia | B12: 17.7 | C12: 90.923077 | D12: 0.20878405
A13: Sierra Leone | B13: 20.815385 | C13: 75.684615 | D13: 0.15434055
A14: Guinea-Bissau | B14: 23.292308 | C14: 87.238462 | D14: 0.18567368
A15: Madagascar | B15: 24.823077 | C15: 83.523077 | D15: 0.12361206
A16: Mozambique | B16: 26.007692 | C16: 80.7 | D16: 0.24987723
A17: Tanzania | B17: 28.946154 | C17: 83.225 | D17: 0.2506588
... A95: Colombia | B95: 98.369231 | C95: 30.941667 | D95: 1.723684
A96: Tuvalu | B96: 98.369231 | C96: 3.6538462
A97: Ecuador | B97: 98.615385 | C97: 15.016667 | D97: 2.4829865
A98: Dominican Republic | B98: 98.646154 | C98: 16.025 | D98: 2.3443912
A99: Romania | B99: 98.961538 | C99: 23.316667 | D99: 4.1300237
A100: Paraguay | B100: 99.030769 | C100: 61.433333 | D100: 1.1190206
A101: Cuba | B101: 99.092308 | C101: 20.866667 | D101: 2.2786121
A102: Tajikistan | B102: 99.176923 | C102: 47.5 | D102: 0.68540746
A103: Viet Nam | B103: 99.207692 | C103: 29.466667 | D103: 2.5239411
A104: Seychelles | B104: 99.338462 | C104: 1.2538462 | D104: 9.654351
A105: Algeria | B105: 99.392308 | C105: 0.15 | D105: 3.8919155
A106: Mexico | B106: 99.430769 | C106: 10.075 | D106: 3.9543049
A107: Iraq | B107: 99.446154 | C107: 1.0333333 | D107: 4.1709221
A108: Russian Federation | B108: 99.469231 | C108: 3.3333333 | D108: 12.505264
... A111: Kyrgyz Republic | B111: 99.492308 | C111: 25.425 | D111: 1.5700199
A112: Montenegro | B112: 99.515385 | C112: 43.025
A113: Palau | B113: 99.523077 | C113: 0.46923077 | D113: 91.376509
A114: British Virgin Islands | B114: 99.553846 | C114: 1.0692308 | D114: 2.1606015
A115: Costa Rica | B115: 99.576923 | C115: 36.225 | D115: 1.6344933
A116: Brazil | B116: 99.584615 | C116: 45.4 | D116: 2.4068433
A117: Venezuela, RB | B117: 99.6 | C117: 17.458333 | D117: 4.9893998
A118: Nauru | B118: 99.607692 | C118: 0.55384615 | D118: 0
A119: Mauritius | B119: 99.623077 | C119: 10.458333 | D119: 3.1310586
A120: Argentina | B120: 99.676923 | C120: 9.525 | D120: 4.2962086
A121: Thailand | B121: 99.692308 | C121: 22.641667 | D121: 3.8546414
...

Sheet Pivot_3
A1: Year | B1: 2022 | F1: Country | G1: Renewable_share
F2: Liberia | G2: 92.8
B3: Values | F3: Uganda | G3: 90.9
A4: Row Labels | B4: Average of Electricity_Access | C4: Average of Renewable_Share | D4: Average of CO2_Per_Capita | F4: Ethiopia | G4: 90.9
A5: South Sudan | B5: 8.4 | F5: Guinea-Bissau | G5: 87.4
A6: Burundi | B6: 10.3 | C6: 83 | D6: 0.069821577 | F6: Madagascar | G6: 83.1
A7: Chad | B7: 11.7 | C7: 70 | D7: 0.15523982 | F7: Burundi | G7: 83
A8: Malawi | B8: 14 | C8: 62.9 | D8: 0.27236978 | F8: Tanzania | G8: 83
A9: Niger | B9: 19.5 | D9: 0.12712561 | F9: Mozambique | G9: 80.7
A10: Burkina Faso | B10: 19.5 | C10: 71.4 | D10: 0.28826199 | F10: Rwanda | G10: 79.9
A11: Sierra Leone | B11: 29.4 | C11: 71.6 | D11: 0.1772181 | F11: Burkina Faso | G11: 71.4
A12: Liberia | B12: 31.8 | C12: 92.8 | D12: 0.16165131
A13: Mozambique | B13: 33.2 | D13: 0.3336942
A14: Madagascar | B14: 36.1 | C14: 83.1 | D14: 0.14403399
A15: Guinea-Bissau | B15: 37.4 | C15: 87.4 | D15: 0.16333187
A16: Tanzania | B16: 45.8 | D16: 0.32316198
A17: Uganda | B17: 47.1 | C17: 90.9 | D17: 0.16811758
A18: Guinea | B18: 47.7 | C18: 66.6 | D18: 0.37145138
A19: Zambia | B19: 47.8 | D19: 0.52454883
A20: Angola | B20: 48.5 | D20: 0.74881095
A21: Mauritania | B21: 49 | C21: 19.6 | D21: 1.0309012
A22: Haiti | B22: 49.3 | D22: 0.29462935
A23: Lesotho | B23: 50 | C23: 34.9 | D23: 0.42915695
A24: Zimbabwe | B24: 50.1 | D24: 0.71922084
A25: Congo, Rep. | B25: 50.6 | D25: 1.3849306
A26: Rwanda | B26: 50.6 | C26: 79.9 | D26: 0.16124791
A27: Mali | B27: 53 | C27: 71.1 | D27: 0.32474827
A28: Eritrea | B28: 53.4 | D28: 0.21994769
A29: Korea, Dem. People's Rep. | B29: 54.7 | D29: 2.2714099
A30: Ethiopia | B30: 55.4 | D30: 0.14622965
A31: Namibia | B31: 56.2 | D31: 1.2388646
A32: Benin | B32: 56.5 | D32: 0.5130564
A33: Togo | B33: 57.2 | D33: 0.28652091
A34: Nigeria | B34: 60.5 | D34: 0.57827104
A35: Sudan | B35: 63.2 | D35: 0.43422331
A36: Djibouti | B36: 65 | C36: 26.9 | D36: 0.76229272
A37: Gambia, The | B37: 65.4 | C37: 47.7 | D37: 0.18771312
A38: Equatorial Guinea | B38: 67 | C38: 4.2 | D38: 2.8215542
A39: Senegal | B39: 67.9 | D39: 0.82395984
A40: Libya | B40: 70 | D40: 8.0530136
...

Sheet Pivot_4
A1: Year | B1: 2022
A3: Row Labels | B3: Average of Electricity_Access
A4: South Sudan | B4: 8.4
A5: Burundi | B5: 10.3
A6: Chad | B6: 11.7
A7: Malawi | B7: 14
A8: Central African Republic | B8: 15.7
A9: Papua New Guinea | B9: 19
A10: Niger | B10: 19.5
A11: Burkina Faso | B11: 19.5
A12: Congo, Dem. Rep. | B12: 21.5
A13: Sierra Leone | B13: 29.4
A14: Grand Total | B14: 16.9

Sheet Pivot_5
A1: Year | B1: 2022
B3: Values
A4: Row Labels | B4: Average of Electricity_Access | C4: Average of Renewable_Share | D4: Average of CO2_Per_Capita | F4: Country | G4: Renewable_Share | H4: CO2_Per_Capita
A5: Afghanistan | B5: 85.3 | C5: 20 | D5: 0.27842096 | F5: =A5 -> Afghanistan | G5: =IF(C5="","",C5) -> 20 | H5: =IF(D5=" ", " ",D5) -> 0.27842096
A6: Albania | B6: 100 | D6: 1.8452576 | F6: =A6 -> Albania | G6: =IF(C6="","",C6) | H6: =IF(D6=" ", " ",D6) -> 1.8452576
A7: Algeria | B7: 100 | D7: 4.1600585 | F7: =A7 -> Algeria | G7: =IF(C7="","",C7) | H7: =IF(D7=" ", " ",D7) -> 4.1600585
A8: Andorra | B8: 100 | C8: 18.7 | F8: =A8 -> Andorra | G8: =IF(C8="","",C8) -> 18.7
A9: Angola | B9: 48.5 | D9: 0.74881095 | F9: =A9 -> Angola | G9: =IF(C9="","",C9) | H9: =IF(D9=" ", " ",D9) -> 0.74881095
A10: Antigua and Barbuda | B10: 100 | C10: 0.9 | D10: 3.6945282 | F10: =A10 -> Antigua and Barbuda | G10: =IF(C10="","",C10) -> 0.9 | H10: =IF(D10=" ", " ",D10) -> 3.6945282
A11: Argentina | B11: 100 | D11: 4.2953117 | F11: =A11 -> Argentina | G11: =IF(C11="","",C11) | H11: =IF(D11=" ", " ",D11) -> 4.2953117
A12: Armenia | B12: 100 | D12: 2.618281 | F12: =A12 -> Armenia | G12: =IF(C12="","",C12) | H12: =IF(D12=" ", " ",D12) -> 2.618281
A13: Aruba | B13: 99.9 | C13: 8.8 | D13: 4.9902153 | F13: =A13 -> Aruba | G13: =IF(C13="","",C13) -> 8.8 | H13: =IF(D13=" ", " ",D13) -> 4.9902153
A14: Australia | B14: 100 | D14: 14.530503 | F14: =A14 -> Australia | G14: =IF(C14="","",C14) | H14: =IF(D14=" ", " ",D14) -> 14.530503
A15: Austria | B15: 100 | D15: 6.9285813 | F15: =A15 -> Austria | G15: =IF(C15="","",C15) | H15: =IF(D15=" ", " ",D15) -> 6.9285813
A16: Azerbaijan | B16: 100 | D16: 3.9128924 | F16: =A16 -> Azerbaijan | G16: =IF(C16="","",C16) | H16: =IF(D16=" ", " ",D16) -> 3.9128924
A17: Bahamas, The | B17: 100 | C17: 1.1 | D17: 3.5355111 | F17: =A17 -> Bahamas, The | G17: =IF(C17="","",C17) -> 1.1 | H17: =IF(D17=" ", " ",D17) -> 3.5355111
A18: Bahrain | B18: 100 | D18: 25.467881 | F18: =A18 -> Bahrain | G18: =IF(C18="","",C18) | H18: =IF(D18=" ", " ",D18) -> 25.467881
A19: Bangladesh | B19: 99.4 | D19: 0.71355653 | F19: =A19 -> Bangladesh | G19: =IF(C19="","",C19) | H19: =IF(D19=" ", " ",D19) -> 0.71355653
A20: Barbados | B20: 100 | C20: 5.5 | D20: 2.4401561 | F20: =A20 -> Barbados | G20: =IF(C20="","",C20) -> 5.5 | H20: =IF(D20=" ", " ",D20) -> 2.4401561
A21: Belarus | B21: 100 | D21: 6.057008 | F21: =A21 -> Belarus | G21: =IF(C21="","",C21) | H21: =IF(D21=" ", " ",D21) -> 6.057008
A22: Belgium | B22: 100 | D22: 7.6776616 | F22: =A22 -> Belgium | G22: =IF(C22="","",C22) | H22: =IF(D22=" ", " ",D22) -> 7.6776616
A23: Belize | B23: 98.6 | C23: 30.8 | D23: 0.88023579 | F23: =A23 -> Belize | G23: =IF(C23="","",C23) -> 30.8 | H23: =IF(D23=" ", " ",D23) -> 0.88023579
A24: Benin | B24: 56.5 | D24: 0.5130564 | F24: =A24 -> Benin | G24: =IF(C24="","",C24) | H24: =IF(D24=" ", " ",D24) -> 0.5130564
A25: Bermuda | B25: 100 | C25: 0.9 | D25: 3.9768954 | F25: =A25 -> Bermuda | G25: =IF(C25="","",C25) -> 0.9 | H25: =IF(D25=" ", " ",D25) -> 3.9768954
A26: Bhutan | B26: 100 | C26: 82.5 | D26: 1.9428516 | F26: =A26 -> Bhutan | G26: =IF(C26="","",C26) -> 82.5 | H26: =IF(D26=" ", " ",D26) -> 1.9428516
A27: Bolivia | B27: 99.9 | D27: 1.936077 | F27: =A27 -> Bolivia | G27: =IF(C27="","",C27) | H27: =IF(D27=" ", " ",D27) -> 1.936077
A28: Botswana | B28: 75.9 | D28: 2.8024601 | F28: =A28 -> Botswana | G28: =IF(C28="","",C28) | H28: =IF(D28=" ", " ",D28) -> 2.8024601
A29: Brazil | B29: 100 | D29: 2.2788958 | F29: =A29 -> Brazil | G29: =IF(C29="","",C29) | H29: =IF(D29=" ", " ",D29) -> 2.2788958
A30: Brunei Darussalam | B30: 100 | D30: 20.943628 | F30: =A30 -> Brunei Darussalam | G30: =IF(C30="","",C30) | H30: =IF(D30=" ", " ",D30) -> 20.943628
A31: Bulgaria | B31: 100 | D31: 7.6476965 | F31: =A31 -> Bulgaria | G31: =IF(C31="","",C31) | H31: =IF(D31=" ", " ",D31) -> 7.6476965
A32: Burkina Faso | B32: 19.5 | C32: 71.4 | D32: 0.28826199 | F32: =A32 -> Burkina Faso | G32: =IF(C32="","",C32) -> 71.4 | H32: =IF(D32=" ", " ",D32) -> 0.28826199
A33: Burundi | B33: 10.3 | C33: 83 | D33: 0.069821577 | F33: =A33 -> Burundi | G33: =IF(C33="","",C33) -> 83 | H33: =IF(D33=" ", " ",D33) -> 0.069821577
A34: Cabo Verde | B34: 97.1 | C34: 21.8 | D34: 1.3085364 | F34: =A34 -> Cabo Verde | G34: =IF(C34="","",C34) -> 21.8 | H34: =IF(D34=" ", " ",D34) -> 1.3085364
A35: Cambodia | B35: 92.3 | D35: 1.0687824 | F35: =A35 -> Cambodia | G35: =IF(C35="","",C35) | H35: =IF(D35=" ", " ",D35) -> 1.0687824
A36: Cameroon | B36: 71 | D36: 0.37759152 | F36: =A36 -> Cameroon | G36: =IF(C36="","",C36) | H36: =IF(D36=" ", " ",D36) -> 0.37759152
A37: Canada | B37: 100 | D37: 14.7893 | F37: =A37 -> Canada | G37: =IF(C37="","",C37) | H37: =IF(D37=" ", " ",D37) -> 14.7893
A38: Cayman Islands | B38: 100 | C38: 0 | D38: 5.0034222 | F38: =A38 -> Cayman Islands | G38: =IF(C38="","",C38) -> 0 | H38: =IF(D38=" ", " ",D38) -> 5.0034222
A39: Chad | B39: 11.7 | C39: 70 | D39: 0.15523982 | F39: =A39 -> Chad | G39: =IF(C39="","",C39) -> 70 | H39: =IF(D39=" ", " ",D39) -> 0.15523982
A40: Chile | B40: 100 | D40: 4.6247498 | F40: =A40 -> Chile | G40: =IF(C40="","",C40) | H40: =IF(D40=" ", " ",D40) -> 4.6247498
A41: China | B41: 100 | D41: 8.8648251 | F41: =A41 -> China | G41: =IF(C41="","",C41) | H41: =IF(D41=" ", " ",D41) -> 8.8648251
...

Sheet Data_QA
A1: Total Rows | B1: =ROWS(Master_Data!$I$2:$I$3329) -> 3328
A2: Unique Keys | B2: =COUNTA(_xlfn.UNIQUE(Master_Data!$I$2:$I$3329)) -> 3328
A3: Duplicate Keys | B3: =B1-B2 -> 0
A5: Column | B5: Missing Count | C5: Missing %
A6: Electricity_Access | B6: =COUNTBLANK(Master_Data!$D$2:$D$3329) -> 0 | C6: =B6/ROWS(Master_Data!$D$2:$D$3329) -> 0
A7: Renewable_Share | B7: =COUNTBLANK(Master_Data!$E$2:$E$3329) -> 315 | C7: =B7/ROWS(Master_Data!$E$2:$E$3329) -> 0.094651442
A8: CO2_Per_Capita | B8: =COUNTBLANK(Master_Data!$F$2:$F$3329) -> 221 | C8: =B8/ROWS(Master_Data!$F$2:$F$3329) -> 0.06640625
A9: EnergyUse_percapita | B9: =COUNTBLANK(Master_Data!$G$2:$G$3329) -> 912 | C9: =B9/ROWS(Master_Data!$G$2:$G$3329) -> 0.27403846
A10: Population | B10: =COUNTBLANK(Master_Data!$H$2:$H$3329) -> 0 | C10: =B10/ROWS(Master_Data!$H$2:$H$3329) -> 0
A12: SECTION C: RANGE CHECKS
A13: Elec_Access below 0 | B13: =COUNTIF(Master_Data!$D:$D,"<0") -> 0 | C13: =IF(B13=0,"✅ PASS","❌ FAIL") -> ✅ PASS
A14: Elec_Access above 100 | B14: =COUNTIF(Master_Data!$D:$D,">100") -> 0 | C14: =IF(B14=0,"✅ PASS","❌ FAIL") -> ✅ PASS
A15: Renewable_Share below 0 | B15: =COUNTIF(Master_Data!$E:$E,"<0") -> 0 | C15: =IF(B15=0,"✅ PASS","❌ FAIL") -> ✅ PASS
A16: Renewable_Share above 100 | B16: =COUNTIF(Master_Data!$E:$E,">100") -> 0 | C16: =IF(B16=0,"✅ PASS","❌ FAIL") -> ✅ PASS
A17: CO2 below 0 | B17: =COUNTIF(Master_Data!$F:$F,"<0") -> 0 | C17: =IF(B17=0,"✅ PASS","❌ FAIL") -> ✅ PASS
A18: Year below 2010 | B18: =COUNTIF(Master_Data!$C:$C,"<2010") -> 0 | C18: =IF(B18=0,"✅ PASS","❌ FAIL") -> ✅ PASS
A19: Year above 2022 | B19: =COUNTIF(Master_Data!$C:$C,">2022") -> 0 | C19: =IF(B19=0,"✅ PASS","❌ FAIL") -> ✅ PASS
A21: SECTION D: OVERALL STATUS
A22: Overall QA Result
A23: =IF(AND(B13=0,B14=0,B15=0,B16=0,B17=0,B18=0,B19=0,B3=0),"✅ ALL CHECKS PASSED — DATA IS CLEAN","❌ ISSUES FOUND — SEE RED CELLS ABOVE") -> ✅ ALL CHECKS PASSED — DATA IS CLEAN

Sheet Master_Data
A1: Country Code | B1: Country Name | C1: Year | D1: Electricity_Access | E1: Renewable_Share | F1: CO2_Per_Capita | G1: EnergyUse_percapita | H1: Population | I1: CountryYear_Key | J1: Elec_Access_YoY | K1: Renew_Share_YoY | L1: CO2_YoY | M1: Total_CO2_Emissions | N1: Electricity_Gap | O1: Energy_Intensity | P1: Income_Group | Q1: Region | R1: Access_Tier | S1: Elec_vs_Global_Avg | T1: Renew_vs_Global_Avg | U1: CO2_vs_Global_Avg | V1: Elec_Progress_Since_2010 | W1: CO2_Progress_Since_2010
A2: ABW | B2: Aruba | C2: 2010 | D2: 93.4 | E2: 5.5 | F2: 4.7408629 | H2: 101838 | I2: =Master_Data!$A2 & "-" & Master_Data!$C2 -> ABW-2010 | J2: =IF(C2=2010,"",IF(D2="","",IFERROR(D2-INDEX($D:$D,MATCH(A2&"-"&(C2-1),$I:$I,0)),""))) | K2: =IF(C2=2010,"",IF(E2="","",IFERROR(E2-INDEX($E:$E,MATCH(A2&"-"&(C2-1),$I:$I,0)),""))) | L2: =IF(C2=2010,"",IF(F2="","",IFERROR(F2-INDEX($F:$F,MATCH(A2&"-"&(C2-1),$I:$I,0)),"" ))) | M2: =IFERROR(F2*H2,"") -> 482800 | N2: =IF(D2="","",100-D2) -> 6.6 | O2: =IFERROR(F2/G2*1000,"") | P2: =IFERROR(VLOOKUP(A2,Ref_Data!$A:$B,2,0),"Unknown") -> High Income | Q2: =IFERROR(VLOOKUP(A2,Ref_Data!$A:$C,3,0),"Unknown") -> Latin America & Caribbean | R2: =IF(D2="","No Data",IF(D2>=95,"Universal Access",IF(D2>=80,"High Access",IF(D2>=50,"Moderate Access",IF(D2>=20,"Low Access","Critical"))))) -> High Access | S2: =IF(D2="","",D2-AVERAGEIF($C:$C,C2,$D:$D)) -> 13.775343 | T2: =IF(E2="","",E2-AVERAGEIF($C:$C,C2,$E:$E)) -> -24.912665 | U2: =IF(F2="","",F2-AVERAGEIF($C:$C,C2,$F:$F)) -> -0.35719627 | V2: =IFERROR(IF(D2="","",D2-INDEX($D:$D,MATCH(A2&"-2010",$I:$I,0))),"") -> 0 | W2: =IFERROR(IF(F2="","",F2-INDEX($F:$F,MATCH(A2&"-2010",$I:$I,0))),"") -> 0
A3: ABW | B3: Aruba | C3: 2011 | D3: 100 | E3: 5.7 | F3: 2.8335819 | H3: 102591 | I3: =Master_Data!$A3 & "-" & Master_Data!$C3 -> ABW-2011 | J3: =IF(C3=2010,"",IF(D3="","",IFERROR(D3-INDEX($D:$D,MATCH(A3&"-"&(C3-1),$I:$I,0)),""))) -> 6.6 | K3: =IF(C3=2010,"",IF(E3="","",IFERROR(E3-INDEX($E:$E,MATCH(A3&"-"&(C3-1),$I:$I,0)),""))) -> 0.2 | L3: =IF(C3=2010,"",IF(F3="","",IFERROR(F3-INDEX($F:$F,MATCH(A3&"-"&(C3-1),$I:$I,0)),"" ))) -> -1.907281 | M3: =IFERROR(F3*H3,"") -> 290700 | N3: =IF(D3="","",100-D3) -> 0 | O3: =IFERROR(F3/G3*1000,"") | P3: =IFERROR(VLOOKUP(A3,Ref_Data!$A:$B,2,0),"Unknown") -> High Income | Q3: =IFERROR(VLOOKUP(A3,Ref_Data!$A:$C,3,0),"Unknown") -> Latin America & Caribbean | R3: =IF(D3="","No Data",IF(D3>=95,"Universal Access",IF(D3>=80,"High Access",IF(D3>=50,"Moderate Access",IF(D3>=20,"Low Access","Critical"))))) -> Universal Access | S3: =IF(D3="","",D3-AVERAGEIF($C:$C,C3,$D:$D)) -> 19.584673 | T3: =IF(E3="","",E3-AVERAGEIF($C:$C,C3,$E:$E)) -> -24.49737 | U3: =IF(F3="","",F3-AVERAGEIF($C:$C,C3,$F:$F)) -> -2.2929515 | V3: =IFERROR(IF(D3="","",D3-INDEX($D:$D,MATCH(A3&"-2010",$I:$I,0))),"") -> 6.6 | W3: =IFERROR(IF(F3="","",F3-INDEX($F:$F,MATCH(A3&"-2010",$I:$I,0))),"") -> -1.907281
A4: ABW | B4: Aruba | C4: 2012 | D4: 100 | E4: 6.9 | F4: 3.6058016 | H4: 104110 | I4: =Master_Data!$A4 & "-" & Master_Data!$C4 -> ABW-2012 | J4: =IF(C4=2010,"",IF(D4="","",IFERROR(D4-INDEX($D:$D,MATCH(A4&"-"&(C4-1),$I:$I,0)),""))) -> 0 | K4: =IF(C4=2010,"",IF(E4="","",IFERROR(E4-INDEX($E:$E,MATCH(A4&"-"&(C4-1),$I:$I,0)),""))) -> 1.2 | L4: =IF(C4=2010,"",IF(F4="","",IFERROR(F4-INDEX($F:$F,MATCH(A4&"-"&(C4-1),$I:$I,0)),"" ))) -> 0.77221966 | M4: =IFERROR(F4*H4,"") -> 375400 | N4: =IF(D4="","",100-D4) -> 0 | O4: =IFERROR(F4/G4*1000,"") | P4: =IFERROR(VLOOKUP(A4,Ref_Data!$A:$B,2,0),"Unknown") -> High Income | Q4: =IFERROR(VLOOKUP(A4,Ref_Data!$A:$C,3,0),"Unknown") -> Latin America & Caribbean | R4: =IF(D4="","No Data",IF(D4>=95,"Universal Access",IF(D4>=80,"High Access",IF(D4>=50,"Moderate Access",IF(D4>=20,"Low Access","Critical"))))) -> Universal Access | S4: =IF(D4="","",D4-AVERAGEIF($C:$C,C4,$D:$D)) -> 18.879195 | T4: =IF(E4="","",E4-AVERAGEIF($C:$C,C4,$E:$E)) -> -23.207129 | U4: =IF(F4="","",F4-AVERAGEIF($C:$C,C4,$F:$F)) -> -1.7997025 | V4: =IFERROR(IF(D4="","",D4-INDEX($D:$D,MATCH(A4&"-2010",$I:$I,0))),"") -> 6.6 | W4: =IFERROR(IF(F4="","",F4-INDEX($F:$F,MATCH(A4&"-2010",$I:$I,0))),"") -> -1.1350614
A5: ABW | B5: Aruba | C5: 2013 | D5: 100 | E5: 6.9 | F5: 3.9063165 | H5: 105675 | I5: =Master_Data!$A5 & "-" & Master_Data!$C5 -> ABW-2013 | J5: =IF(C5=2010,"",IF(D5="","",IFERROR(D5-INDEX($D:$D,MATCH(A5&"-"&(C5-1),$I:$I,0)),""))) -> 0 | K5: =IF(C5=2010,"",IF(E5="","",IFERROR(E5-INDEX($E:$E,MATCH(A5&"-"&(C5-1),$I:$I,0)),""))) -> 0 | L5: =IF(C5=2010,"",IF(F5="","",IFERROR(F5-INDEX($F:$F,MATCH(A5&"-"&(C5-1),$I:$I,0)),"" ))) -> 0.30051498 | M5: =IFERROR(F5*H5,"") -> 412800 | N5: =IF(D5="","",100-D5) -> 0 | O5: =IFERROR(F5/G5*1000,"") | P5: =IFERROR(VLOOKUP(A5,Ref_Data!$A:$B,2,0),"Unknown") -> High Income | Q5: =IFERROR(VLOOKUP(A5,Ref_Data!$A:$C,3,0),"Unknown") -> Latin America & Caribbean | R5: =IF(D5="","No Data",IF(D5>=95,"Universal Access",IF(D5>=80,"High Access",IF(D5>=50,"Moderate Access",IF(D5>=20,"Low Access","Critical"))))) -> Universal Access | S5: =IF(D5="","",D5-AVERAGEIF($C:$C,C5,$D:$D)) -> 18.287462 | T5: =IF(E5="","",E5-AVERAGEIF($C:$C,C5,$E:$E)) -> -23.40164 | U5: =IF(F5="","",F5-AVERAGEIF($C:$C,C5,$F:$F)) -> -1.0620539 | V5: =IFERROR(IF(D5="","",D5-INDEX($D:$D,MATCH(A5&"-2010",$I:$I,0))),"") -> 6.6 | W5: =IFERROR(IF(F5="","",F5-INDEX($F:$F,MATCH(A5&"-2010",$I:$I,0))),"") -> -0.8345464
A6: ABW | B6: Aruba | C6: 2014 | D6: 100 | E6: 6.9 | F6: 4.1298791 | H6: 106807 | I6: =Master_Data!$A6 & "-" & Master_Data!$C6 -> ABW-2014 | J6: =IF(C6=2010,"",IF(D6="","",IFERROR(D6-INDEX($D:$D,MATCH(A6&"-"&(C6-1),$I:$I,0)),""))) -> 0 | K6: =IF(C6=2010,"",IF(E6="","",IFERROR(E6-INDEX($E:$E,MATCH(A6&"-"&(C6-1),$I:$I,0)),""))) -> 0 | L6: =IF(C6=2010,"",IF(F6="","",IFERROR(F6-INDEX($F:$F,MATCH(A6&"-"&(C6-1),$I:$I,0)),"" ))) -> 0.22356259 | M6: =IFERROR(F6*H6,"") -> 441100 | N6: =IF(D6="","",100-D6) -> 0 | O6: =IFERROR(F6/G6*1000,"") | P6: =IFERROR(VLOOKUP(A6,Ref_Data!$A:$B,2,0),"Unknown") -> High Income | Q6: =IFERROR(VLOOKUP(A6,Ref_Data!$A:$C,3,0),"Unknown") -> Latin America & Caribbean | R6: =IF(D6="","No Data",IF(D6>=95,"Universal Access",IF(D6>=80,"High Access",IF(D6>=50,"Moderate Access",IF(D6>=20,"Low Access","Critical"))))) -> Universal Access | S6: =IF(D6="","",D6-AVERAGEIF($C:$C,C6,$D:$D)) -> 17.559097 | T6: =IF(E6="","",E6-AVERAGEIF($C:$C,C6,$E:$E)) -> -23.211727 | U6: =IF(F6="","",F6-AVERAGEIF($C:$C,C6,$F:$F)) -> -0.66140777 | V6: =IFERROR(IF(D6="","",D6-INDEX($D:$D,MATCH(A6&"-2010",$I:$I,0))),"") -> 6.6 | W6: =IFERROR(IF(F6="","",F6-INDEX($F:$F,MATCH(A6&"-2010",$I:$I,0))),"") -> -0.61098381
A7: ABW | B7: Aruba | C7: 2015 | D7: 100 | E7: 6.7 | F7: 4.2861379 | H7: 107906 | I7: =Master_Data!$A7 & "-" & Master_Data!$C7 -> ABW-2015 | J7: =IF(C7=2010,"",IF(D7="","",IFERROR(D7-INDEX($D:$D,MATCH(A7&"-"&(C7-1),$I:$I,0)),""))) -> 0 | K7: =IF(C7=2010,"",IF(E7="","",IFERROR(E7-INDEX($E:$E,MATCH(A7&"-"&(C7-1),$I:$I,0)),""))) -> -0.2 | L7: =IF(C7=2010,"",IF(F7="","",IFERROR(F7-INDEX($F:$F,MATCH(A7&"-"&(C7-1),$I:$I,0)),"" ))) -> 0.15625881 | M7: =IFERROR(F7*H7,"") -> 462500 | N7: =IF(D7="","",100-D7) -> 0 | O7: =IFERROR(F7/G7*1000,"") | P7: =IFERROR(VLOOKUP(A7,Ref_Data!$A:$B,2,0),"Unknown") -> High Income | Q7: =IFERROR(VLOOKUP(A7,Ref_Data!$A:$C,3,0),"Unknown") -> Latin America & Caribbean | R7: =IF(D7="","No Data",IF(D7>=95,"Universal Access",IF(D7>=80,"High Access",IF(D7>=50,"Moderate Access",IF(D7>=20,"Low Access","Critical"))))) -> Universal Access | S7: =IF(D7="","",D7-AVERAGEIF($C:$C,C7,$D:$D)) -> 16.984761 | T7: =IF(E7="","",E7-AVERAGEIF($C:$C,C7,$E:$E)) -> -23.215157 | U7: =IF(F7="","",F7-AVERAGEIF($C:$C,C7,$F:$F)) -> -0.42330343 | V7: =IFERROR(IF(D7="","",D7-INDEX($D:$D,MATCH(A7&"-2010",$I:$I,0))),"") -> 6.6 | W7: =IFERROR(IF(F7="","",F7-INDEX($F:$F,MATCH(A7&"-2010",$I:$I,0))),"") -> -0.454725
A8: ABW | B8: Aruba | C8: 2016 | D8: 100 | E8: 7 | F8: 4.4643925 | H8: 108727 | I8: =Master_Data!$A8 & "-" & Master_Data!$C8 -> ABW-2016 | J8: =IF(C8=2010,"",IF(D8="","",IFERROR(D8-INDEX($D:$D,MATCH(A8&"-"&(C8-1),$I:$I,0)),""))) -> 0 | K8: =IF(C8=2010,"",IF(E8="","",IFERROR(E8-INDEX($E:$E,MATCH(A8&"-"&(C8-1),$I:$I,0)),""))) -> 0.3 | L8: =IF(C8=2010,"",IF(F8="","",IFERROR(F8-INDEX($F:$F,MATCH(A8&"-"&(C8-1),$I:$I,0)),"" ))) -> 0.17825453 | M8: =IFERROR(F8*H8,"") -> 485400 | N8: =IF(D8="","",100-D8) -> 0 | O8: =IFERROR(F8/G8*1000,"") | P8: =IFERROR(VLOOKUP(A8,Ref_Data!$A:$B,2,0),"Unknown") -> High Income | Q8: =IFERROR(VLOOKUP(A8,Ref_Data!$A:$C,3,0),"Unknown") -> Latin America & Caribbean | R8: =IF(D8="","No Data",IF(D8>=95,"Universal Access",IF(D8>=80,"High Access",IF(D8>=50,"Moderate Access",IF(D8>=20,"Low Access","Critical"))))) -> Universal Access | S8: =IF(D8="","",D8-AVERAGEIF($C:$C,C8,$D:$D)) -> 15.905249 | T8: =IF(E8="","",E8-AVERAGEIF($C:$C,C8,$E:$E)) -> -22.706058 | U8: =IF(F8="","",F8-AVERAGEIF($C:$C,C8,$F:$F)) -> -0.20997933 | V8: =IFERROR(IF(D8="","",D8-INDEX($D:$D,MATCH(A8&"-2010",$I:$I,0))),"") -> 6.6 | W8: =IFERROR(IF(F8="","",F8-INDEX($F:$F,MATCH(A8&"-2010",$I:$I,0))),"") -> -0.27647047
A9: ABW | B9: Aruba | C9: 2017 | D9: 100 | E9: 6.8 | F9: 4.2957649 | H9: 108735 | I9: =Master_Data!$A9 & "-" & Master_Data!$C9 -> ABW-2017 | J9: =IF(C9=2010,"",IF(D9="","",IFERROR(D9-INDEX($D:$D,MATCH(A9&"-"&(C9-1),$I:$I,0)),""))) -> 0 | K9: =IF(C9=2010,"",IF(E9="","",IFERROR(E9-INDEX($E:$E,MATCH(A9&"-"&(C9-1),$I:$I,0)),""))) -> -0.2 | L9: =IF(C9=2010,"",IF(F9="","",IFERROR(F9-INDEX($F:$F,MATCH(A9&"-"&(C9-1),$I:$I,0)),"" ))) -> -0.16862754 | M9: =IFERROR(F9*H9,"") -> 467100 | N9: =IF(D9="","",100-D9) -> 0 | O9: =IFERROR(F9/G9*1000,"") | P9: =IFERROR(VLOOKUP(A9,Ref_Data!$A:$B,2,0),"Unknown") -> High Income | Q9: =IFERROR(VLOOKUP(A9,Ref_Data!$A:$C,3,0),"Unknown") -> Latin America & Caribbean | R9: =IF(D9="","No Data",IF(D9>=95,"Universal Access",IF(D9>=80,"High Access",IF(D9>=50,"Moderate Access",IF(D9>=20,"Low Access","Critical"))))) -> Universal Access | S9: =IF(D9="","",D9-AVERAGEIF($C:$C,C9,$D:$D)) -> 15.146092 | T9: =IF(E9="","",E9-AVERAGEIF($C:$C,C9,$E:$E)) -> -22.741519 | U9: =IF(F9="","",F9-AVERAGEIF($C:$C,C9,$F:$F)) -> -0.38198613 | V9: =IFERROR(IF(D9="","",D9-INDEX($D:$D,MATCH(A9&"-2010",$I:$I,0))),"") -> 6.6 | W9: =IFERROR(IF(F9="","",F9-INDEX($F:$F,MATCH(A9&"-2010",$I:$I,0))),"") -> -0.44509801
A10: ABW | B10: Aruba | C10: 2018 | D10: 100 | E10: 8.6 | F10: 4.2724134 | H10: 108908 | I10: =Master_Data!$A10 & "-" & Master_Data!$C10 -> ABW-2018 | J10: =IF(C10=2010,"",IF(D10="","",IFERROR(D10-INDEX($D:$D,MATCH(A10&"-"&(C10-1),$I:$I,0)),""))) -> 0 | K10: =IF(C10=2010,"",IF(E10="","",IFERROR(E10-INDEX($E:$E,MATCH(A10&"-"&(C10-1),$I:$I,0)),""))) -> 1.8 | L10: =IF(C10=2010,"",IF(F10="","",IFERROR(F10-INDEX($F:$F,MATCH(A10&"-"&(C10-1),$I:$I,0)),"" ))) -> -0.02335152 | M10: =IFERROR(F10*H10,"") -> 465300 | N10: =IF(D10="","",100-D10) -> 0 | O10: =IFERROR(F10/G10*1000,"") | P10: =IFERROR(VLOOKUP(A10,Ref_Data!$A:$B,2,0),"Unknown") -> High Income | Q10: =IFERROR(VLOOKUP(A10,Ref_Data!$A:$C,3,0),"Unknown") -> Latin America & Caribbean | R10: =IF(D10="","No Data",IF(D10>=95,"Universal Access",IF(D10>=80,"High Access",IF(D10>=50,"Moderate Access",IF(D10>=20,"Low Access","Critical"))))) -> Universal Access | S10: =IF(D10="","",D10-AVERAGEIF($C:$C,C10,$D:$D)) -> 14.516199 | T10: =IF(E10="","",E10-AVERAGEIF($C:$C,C10,$E:$E)) -> -20.96303 | U10: =IF(F10="","",F10-AVERAGEIF($C:$C,C10,$F:$F)) -> -0.4384556 | V10: =IFERROR(IF(D10="","",D10-INDEX($D:$D,MATCH(A10&"-2010",$I:$I,0))),"") -> 6.6 | W10: =IFERROR(IF(F10="","",F10-INDEX($F:$F,MATCH(A10&"-2010",$I:$I,0))),"") -> -0.46844953
A11: ABW | B11: Aruba | C11: 2019 | D11: 100 | E11: 8.3 | F11: 4.6656227 | H11: 109203 | I11: =Master_Data!$A11 & "-" & Master_Data!$C11 -> ABW-2019 | J11: =IF(C11=2010,"",IF(D11="","",IFERROR(D11-INDEX($D:$D,MATCH(A11&"-"&(C11-1),$I:$I,0)),""))) -> 0 | K11: =IF(C11=2010,"",IF(E11="","",IFERROR(E11-INDEX($E:$E,MATCH(A11&"-"&(C11-1),$I:$I,0)),""))) -> -0.3 | L11: =IF(C11=2010,"",IF(F11="","",IFERROR(F11-INDEX($F:$F,MATCH(A11&"-"&(C11-1),$I:$I,0)),"" ))) -> 0.39320933 | M11: =IFERROR(F11*H11,"") -> 509500 | N11: =IF(D11="","",100-D11) -> 0 | O11: =IFERROR(F11/G11*1000,"") | P11: =IFERROR(VLOOKUP(A11,Ref_Data!$A:$B,2,0),"Unknown") -> High Income | Q11: =IFERROR(VLOOKUP(A11,Ref_Data!$A:$C,3,0),"Unknown") -> Latin America & Caribbean | R11: =IF(D11="","No Data",IF(D11>=95,"Universal Access",IF(D11>=80,"High Access",IF(D11>=50,"Moderate Access",IF(D11>=20,"Low Access","Critical"))))) -> Universal Access | S11: =IF(D11="","",D11-AVERAGEIF($C:$C,C11,$D:$D)) -> 13.958623 | T11: =IF(E11="","",E11-AVERAGEIF($C:$C,C11,$E:$E)) -> -21.162191 | U11: =IF(F11="","",F11-AVERAGEIF($C:$C,C11,$F:$F)) -> -0.017778557 | V11: =IFERROR(IF(D11="","",D11-INDEX($D:$D,MATCH(A11&"-2010",$I:$I,0))),"") -> 6.6 | W11: =IFERROR(IF(F11="","",F11-INDEX($F:$F,MATCH(A11&"-2010",$I:$I,0))),"") -> -0.0752402
A12: ABW | B12: Aruba | C12: 2020 | D12: 100 | E12: 9.1 | F12: 4.5005387 | H12: 108587 | I12: =Master_Data!$A12 & "-" & Master_Data!$C12 -> ABW-2020 | J12: =IF(C12=2010,"",IF(D12="","",IFERROR(D12-INDEX($D:$D,MATCH(A12&"-"&(C12-1),$I:$I,0)),""))) -> 0 | K12: =IF(C12=2010,"",IF(E12="","",IFERROR(E12-INDEX($E:$E,MATCH(A12&"-"&(C12-1),$I:$I,0)),""))) -> 0.8 | L12: =IF(C12=2010,"",IF(F12="","",IFERROR(F12-INDEX($F:$F,MATCH(A12&"-"&(C12-1),$I:$I,0)),"" ))) -> -0.165084 | M12: =IFERROR(F12*H12,"") -> 488700 | N12: =IF(D12="","",100-D12) -> 0 | O12: =IFERROR(F12/G12*1000,"") | P12: =IFERROR(VLOOKUP(A12,Ref_Data!$A:$B,2,0),"Unknown") -> High Income | Q12: =IFERROR(VLOOKUP(A12,Ref_Data!$A:$C,3,0),"Unknown") -> Latin America & Caribbean | R12: =IF(D12="","No Data",IF(D12>=95,"Universal Access",IF(D12>=80,"High Access",IF(D12>=50,"Moderate Access",IF(D12>=20,"Low Access","Critical"))))) -> Universal Access | S12: =IF(D12="","",D12-AVERAGEIF($C:$C,C12,$D:$D)) -> 13.426165 | T12: =IF(E12="","",E12-AVERAGEIF($C:$C,C12,$E:$E)) -> -21.434853 | U12: =IF(F12="","",F12-AVERAGEIF($C:$C,C12,$F:$F)) -> 0.099791103 | V12: =IFERROR(IF(D12="","",D12-INDEX($D:$D,MATCH(A12&"-2010",$I:$I,0))),"") -> 6.6 | W12: =IFERROR(IF(F12="","",F12-INDEX($F:$F,MATCH(A12&"-2010",$I:$I,0))),"") -> -0.2403242
A13: ABW | B13: Aruba | C13: 2021 | D13: 100 | E13: 8.8 | F13: 4.7112349 | H13: 107700 | I13: =Master_Data!$A13 & "-" & Master_Data!$C13 -> ABW-2021 | J13: =IF(C13=2010,"",IF(D13="","",IFERROR(D13-INDEX($D:$D,MATCH(A13&"-"&(C13-1),$I:$I,0)),""))) -> 0 | K13: =IF(C13=2010,"",IF(E13="","",IFERROR(E13-INDEX($E:$E,MATCH(A13&"-"&(C13-1),$I:$I,0)),""))) -> -0.3 | L13: =IF(C13=2010,"",IF(F13="","",IFERROR(F13-INDEX($F:$F,MATCH(A13&"-"&(C13-1),$I:$I,0)),"" ))) -> 0.21069617 | M13: =IFERROR(F13*H13,"") -> 507400 | N13: =IF(D13="","",100-D13) -> 0 | O13: =IFERROR(F13/G13*1000,"") | P13: =IFERROR(VLOOKUP(A13,Ref_Data!$A:$B,2,0),"Unknown") -> High Income | Q13: =IFERROR(VLOOKUP(A13,Ref_Data!$A:$C,3,0),"Unknown") -> Latin America & Caribbean | R13: =IF(D13="","No Data",IF(D13>=95,"Universal Access",IF(D13>=80,"High Access",IF(D13>=50,"Moderate Access",IF(D13>=20,"Low Access","Critical"))))) -> Universal Access | S13: =IF(D13="","",D13-AVERAGEIF($C:$C,C13,$D:$D)) -> 12.874831 | T13: =IF(E13="","",E13-AVERAGEIF($C:$C,C13,$E:$E)) -> -20.803382 | U13: =IF(F13="","",F13-AVERAGEIF($C:$C,C13,$F:$F)) -> 0.13050057 | V13: =IFERROR(IF(D13="","",D13-INDEX($D:$D,MATCH(A13&"-2010",$I:$I,0))),"") -> 6.6 | W13: =IFERROR(IF(F13="","",F13-INDEX($F:$F,MATCH(A13&"-2010",$I:$I,0))),"") -> -0.029628027
... A27: AFG | B27: Afghanistan | C27: 2022 | D27: 85.3 | E27: 20 | F27: 0.27842096 | H27: 40578842 | I27: =Master_Data!$A27 & "-" & Master_Data!$C27 -> AFG-2022 | J27: =IF(C27=2010,"",IF(D27="","",IFERROR(D27-INDEX($D:$D,MATCH(A27&"-"&(C27-1),$I:$I,0)),""))) -> -12.4 | K27: =IF(C27=2010,"",IF(E27="","",IFERROR(E27-INDEX($E:$E,MATCH(A27&"-"&(C27-1),$I:$I,0)),""))) -> 0 | L27: =IF(C27=2010,"",IF(F27="","",IFERROR(F27-INDEX($F:$F,MATCH(A27&"-"&(C27-1),$I:$I,0)),"" ))) -> -0.033735829 | M27: =IFERROR(F27*H27,"") -> 11298000 | N27: =IF(D27="","",100-D27) -> 14.7 | O27: =IFERROR(F27/G27*1000,"") | P27: =IFERROR(VLOOKUP(A27,Ref_Data!$A:$B,2,0),"Unknown") -> Low Income | Q27: =IFERROR(VLOOKUP(A27,Ref_Data!$A:$C,3,0),"Unknown") -> South Asia | R27: =IF(D27="","No Data",IF(D27>=95,"Universal Access",IF(D27>=80,"High Access",IF(D27>=50,"Moderate Access",IF(D27>=20,"Low Access","Critical"))))) -> High Access | S27: =IF(D27="","",D27-AVERAGEIF($C:$C,C27,$D:$D)) -> -2.1140537 | T27: =IF(E27="","",E27-AVERAGEIF($C:$C,C27,$E:$E)) -> -10.421739 | U27: =IF(F27="","",F27-AVERAGEIF($C:$C,C27,$F:$F)) -> -4.2723801 | V27: =IFERROR(IF(D27="","",D27-INDEX($D:$D,MATCH(A27&"-2010",$I:$I,0))),"") -> 42.6 | W27: =IFERROR(IF(F27="","",F27-INDEX($F:$F,MATCH(A27&"-2010",$I:$I,0))),"") -> 0.000229214
A28: AGO | B28: Angola | C28: 2010 | D28: 35 | E28: 53.1 | F28: 0.97617818 | G28: 487.28107 | H28: 23294825 | I28: =Master_Data!$A28 & "-" & Master_Data!$C28 -> AGO-2010 | J28: =IF(C28=2010,"",IF(D28="","",IFERROR(D28-INDEX($D:$D,MATCH(A28&"-"&(C28-1),$I:$I,0)),""))) | K28: =IF(C28=2010,"",IF(E28="","",IFERROR(E28-INDEX($E:$E,MATCH(A28&"-"&(C28-1),$I:$I,0)),""))) | L28: =IF(C28=2010,"",IF(F28="","",IFERROR(F28-INDEX($F:$F,MATCH(A28&"-"&(C28-1),$I:$I,0)),"" ))) | M28: =IFERROR(F28*H28,"") -> 22739900 | N28: =IF(D28="","",100-D28) -> 65 | O28: =IFERROR(F28/G28*1000,"") -> 2.0033164 | P28: =IFERROR(VLOOKUP(A28,Ref_Data!$A:$B,2,0),"Unknown") -> Lower Middle Income | Q28: =IFERROR(VLOOKUP(A28,Ref_Data!$A:$C,3,0),"Unknown") -> Sub-Saharan Africa | R28: =IF(D28="","No Data",IF(D28>=95,"Universal Access",IF(D28>=80,"High Access",IF(D28>=50,"Moderate Access",IF(D28>=20,"Low Access","Critical"))))) -> Low Access | S28: =IF(D28="","",D28-AVERAGEIF($C:$C,C28,$D:$D)) -> -44.624657 | T28: =IF(E28="","",E28-AVERAGEIF($C:$C,C28,$E:$E)) -> 22.687335 | U28: =IF(F28="","",F28-AVERAGEIF($C:$C,C28,$F:$F)) -> -4.121881 | V28: =IFERROR(IF(D28="","",D28-INDEX($D:$D,MATCH(A28&"-2010",$I:$I,0))),"") -> 0 | W28: =IFERROR(IF(F28="","",F28-INDEX($F:$F,MATCH(A28&"-2010",$I:$I,0))),"") -> 0
A29: AGO | B29: Angola | C29: 2011 | D29: 34.6 | E29: 51.7 | F29: 0.97653631 | G29: 486.23537 | H29: 24218352 | I29: =Master_Data!$A29 & "-" & Master_Data!$C29 -> AGO-2011 | J29: =IF(C29=2010,"",IF(D29="","",IFERROR(D29-INDEX($D:$D,MATCH(A29&"-"&(C29-1),$I:$I,0)),""))) -> -0.4 | K29: =IF(C29=2010,"",IF(E29="","",IFERROR(E29-INDEX($E:$E,MATCH(A29&"-"&(C29-1),$I:$I,0)),""))) -> -1.4 | L29: =IF(C29=2010,"",IF(F29="","",IFERROR(F29-INDEX($F:$F,MATCH(A29&"-"&(C29-1),$I:$I,0)),"" ))) -> 0.000358121 | M29: =IFERROR(F29*H29,"") -> 23650100 | N29: =IF(D29="","",100-D29) -> 65.4 | O29: =IFERROR(F29/G29*1000,"") -> 2.0083613 | P29: =IFERROR(VLOOKUP(A29,Ref_Data!$A:$B,2,0),"Unknown") -> Lower Middle Income | Q29: =IFERROR(VLOOKUP(A29,Ref_Data!$A:$C,3,0),"Unknown") -> Sub-Saharan Africa | R29: =IF(D29="","No Data",IF(D29>=95,"Universal Access",IF(D29>=80,"High Access",IF(D29>=50,"Moderate Access",IF(D29>=20,"Low Access","Critical"))))) -> Low Access | S29: =IF(D29="","",D29-AVERAGEIF($C:$C,C29,$D:$D)) -> -45.815327 | T29: =IF(E29="","",E29-AVERAGEIF($C:$C,C29,$E:$E)) -> 21.50263 | U29: =IF(F29="","",F29-AVERAGEIF($C:$C,C29,$F:$F)) -> -4.1499971 | V29: =IFERROR(IF(D29="","",D29-INDEX($D:$D,MATCH(A29&"-2010",$I:$I,0))),"") -> -0.4 | W29: =IFERROR(IF(F29="","",F29-INDEX($F:$F,MATCH(A29&"-2010",$I:$I,0))),"") -> 0.000358121
A30: AGO | B30: Angola | C30: 2012 | D30: 37.3 | E30: 49 | F30: 0.98168222 | G30: 531.24332 | H30: 25177394 | I30: =Master_Data!$A30 & "-" & Master_Data!$C30 -> AGO-2012 | J30: =IF(C30=2010,"",IF(D30="","",IFERROR(D30-INDEX($D:$D,MATCH(A30&"-"&(C30-1),$I:$I,0)),""))) -> 2.7 | K30: =IF(C30=2010,"",IF(E30="","",IFERROR(E30-INDEX($E:$E,MATCH(A30&"-"&(C30-1),$I:$I,0)),""))) -> -2.7 | L30: =IF(C30=2010,"",IF(F30="","",IFERROR(F30-INDEX($F:$F,MATCH(A30&"-"&(C30-1),$I:$I,0)),"" ))) -> 0.005145913 | M30: =IFERROR(F30*H30,"") -> 24716200 | N30: =IF(D30="","",100-D30) -> 62.7 | O30: =IFERROR(F30/G30*1000,"") -> 1.8478956 | P30: =IFERROR(VLOOKUP(A30,Ref_Data!$A:$B,2,0),"Unknown") -> Lower Middle Income | Q30: =IFERROR(VLOOKUP(A30,Ref_Data!$A:$C,3,0),"Unknown") -> Sub-Saharan Africa | R30: =IF(D30="","No Data",IF(D30>=95,"Universal Access",IF(D30>=80,"High Access",IF(D30>=50,"Moderate Access",IF(D30>=20,"Low Access","Critical"))))) -> Low Access | S30: =IF(D30="","",D30-AVERAGEIF($C:$C,C30,$D:$D)) -> -43.820805 | T30: =IF(E30="","",E30-AVERAGEIF($C:$C,C30,$E:$E)) -> 18.892871 | U30: =IF(F30="","",F30-AVERAGEIF($C:$C,C30,$F:$F)) -> -4.4238218 | V30: =IFERROR(IF(D30="","",D30-INDEX($D:$D,MATCH(A30&"-2010",$I:$I,0))),"") -> 2.3 | W30: =IFERROR(IF(F30="","",F30-INDEX($F:$F,MATCH(A30&"-2010",$I:$I,0))),"") -> 0.005504034
A31: AGO | B31: Angola | C31: 2013 | D31: 38.4 | E31: 46.8 | F31: 1.0905264 | G31: 512.0218 | H31: 26165620 | I31: =Master_Data!$A31 & "-" & Master_Data!$C31 -> AGO-2013 | J31: =IF(C31=2010,"",IF(D31="","",IFERROR(D31-INDEX($D:$D,MATCH(A31&"-"&(C31-1),$I:$I,0)),""))) -> 1.1 | K31: =IF(C31=2010,"",IF(E31="","",IFERROR(E31-INDEX($E:$E,MATCH(A31&"-"&(C31-1),$I:$I,0)),""))) -> -2.2 | L31: =IF(C31=2010,"",IF(F31="","",IFERROR(F31-INDEX($F:$F,MATCH(A31&"-"&(C31-1),$I:$I,0)),"" ))) -> 0.10884421 | M31: =IFERROR(F31*H31,"") -> 28534300 | N31: =IF(D31="","",100-D31) -> 61.6 | O31: =IFERROR(F31/G31*1000,"") -> 2.1298437 | P31: =IFERROR(VLOOKUP(A31,Ref_Data!$A:$B,2,0),"Unknown") -> Lower Middle Income | Q31: =IFERROR(VLOOKUP(A31,Ref_Data!$A:$C,3,0),"Unknown") -> Sub-Saharan Africa | R31: =IF(D31="","No Data",IF(D31>=95,"Universal Access",IF(D31>=80,"High Access",IF(D31>=50,"Moderate Access",IF(D31>=20,"Low Access","Critical"))))) -> Low Access | S31: =IF(D31="","",D31-AVERAGEIF($C:$C,C31,$D:$D)) -> -43.312538 | T31: =IF(E31="","",E31-AVERAGEIF($C:$C,C31,$E:$E)) -> 16.49836 | U31: =IF(F31="","",F31-AVERAGEIF($C:$C,C31,$F:$F)) -> -3.877844 | V31: =IFERROR(IF(D31="","",D31-INDEX($D:$D,MATCH(A31&"-2010",$I:$I,0))),"") -> 3.4 | W31: =IFERROR(IF(F31="","",F31-INDEX($F:$F,MATCH(A31&"-2010",$I:$I,0))),"") -> 0.11434824
A32: AGO | B32: Angola | C32: 2014 | D32: 32 | E32: 47.5 | F32: 1.1372027 | G32: 447.16033 | H32: 27160769 | I32: =Master_Data!$A32 & "-" & Master_Data!$C32 -> AGO-2014 | J32: =IF(C32=2010,"",IF(D32="","",IFERROR(D32-INDEX($D:$D,MATCH(A32&"-"&(C32-1),$I:$I,0)),""))) -> -6.4 | K32: =IF(C32=2010,"",IF(E32="","",IFERROR(E32-INDEX($E:$E,MATCH(A32&"-"&(C32-1),$I:$I,0)),""))) -> 0.7 | L32: =IF(C32=2010,"",IF(F32="","",IFERROR(F32-INDEX($F:$F,MATCH(A32&"-"&(C32-1),$I:$I,0)),"" ))) -> 0.046676282 | M32: =IFERROR(F32*H32,"") -> 30887300 | N32: =IF(D32="","",100-D32) -> 68 | O32: =IFERROR(F32/G32*1000,"") -> 2.5431655 | P32: =IFERROR(VLOOKUP(A32,Ref_Data!$A:$B,2,0),"Unknown") -> Lower Middle Income | Q32: =IFERROR(VLOOKUP(A32,Ref_Data!$A:$C,3,0),"Unknown") -> Sub-Saharan Africa | R32: =IF(D32="","No Data",IF(D32>=95,"Universal Access",IF(D32>=80,"High Access",IF(D32>=50,"Moderate Access",IF(D32>=20,"Low Access","Critical"))))) -> Low Access | S32: =IF(D32="","",D32-AVERAGEIF($C:$C,C32,$D:$D)) -> -50.440903 | T32: =IF(E32="","",E32-AVERAGEIF($C:$C,C32,$E:$E)) -> 17.388273 | U32: =IF(F32="","",F32-AVERAGEIF($C:$C,C32,$F:$F)) -> -3.6540842 | V32: =IFERROR(IF(D32="","",D32-INDEX($D:$D,MATCH(A32&"-2010",$I:$I,0))),"") -> -3 | W32: =IFERROR(IF(F32="","",F32-INDEX($F:$F,MATCH(A32&"-2010",$I:$I,0))),"") -> 0.16102452
A33: AGO | B33: Angola | C33: 2015 | D33: 42 | E33: 47.1 | F33: 1.1750386 | G33: 517.52521 | H33: 28157798 | I33: =Master_Data!$A33 & "-" & Master_Data!$C33 -> AGO-2015 | J33: =IF(C33=2010,"",IF(D33="","",IFERROR(D33-INDEX($D:$D,MATCH(A33&"-"&(C33-1),$I:$I,0)),""))) -> 10 | K33: =IF(C33=2010,"",IF(E33="","",IFERROR(E33-INDEX($E:$E,MATCH(A33&"-"&(C33-1),$I:$I,0)),""))) -> -0.4 | L33: =IF(C33=2010,"",IF(F33="","",IFERROR(F33-INDEX($F:$F,MATCH(A33&"-"&(C33-1),$I:$I,0)),"" ))) -> 0.03783591 | M33: =IFERROR(F33*H33,"") -> 33086500 | N33: =IF(D33="","",100-D33) -> 58 | O33: =IFERROR(F33/G33*1000,"") -> 2.2704954 | P33: =IFERROR(VLOOKUP(A33,Ref_Data!$A:$B,2,0),"Unknown") -> Lower Middle Income | Q33: =IFERROR(VLOOKUP(A33,Ref_Data!$A:$C,3,0),"Unknown") -> Sub-Saharan Africa | R33: =IF(D33="","No Data",IF(D33>=95,"Universal Access",IF(D33>=80,"High Access",IF(D33>=50,"Moderate Access",IF(D33>=20,"Low Access","Critical"))))) -> Low Access | S33: =IF(D33="","",D33-AVERAGEIF($C:$C,C33,$D:$D)) -> -41.015239 | T33: =IF(E33="","",E33-AVERAGEIF($C:$C,C33,$E:$E)) -> 17.184843 | U33: =IF(F33="","",F33-AVERAGEIF($C:$C,C33,$F:$F)) -> -3.5344028 | V33: =IFERROR(IF(D33="","",D33-INDEX($D:$D,MATCH(A33&"-2010",$I:$I,0))),"") -> 7 | W33: =IFERROR(IF(F33="","",F33-INDEX($F:$F,MATCH(A33&"-2010",$I:$I,0))),"") -> 0.19886043
A34: AGO | B34: Angola | C34: 2016 | D34: 41.8 | E34: 48.1 | F34: 1.0716761 | G34: 462.93499 | H34: 29183070 | I34: =Master_Data!$A34 & "-" & Master_Data!$C34 -> AGO-2016 | J34: =IF(C34=2010,"",IF(D34="","",IFERROR(D34-INDEX($D:$D,MATCH(A34&"-"&(C34-1),$I:$I,0)),""))) -> -0.2 | K34: =IF(C34=2010,"",IF(E34="","",IFERROR(E34-INDEX($E:$E,MATCH(A34&"-"&(C34-1),$I:$I,0)),""))) -> 1 | L34: =IF(C34=2010,"",IF(F34="","",IFERROR(F34-INDEX($F:$F,MATCH(A34&"-"&(C34-1),$I:$I,0)),"" ))) -> -0.10336247 | M34: =IFERROR(F34*H34,"") -> 31274800 | N34: =IF(D34="","",100-D34) -> 58.2 | O34: =IFERROR(F34/G34*1000,"") -> 2.3149603 | P34: =IFERROR(VLOOKUP(A34,Ref_Data!$A:$B,2,0),"Unknown") -> Lower Middle Income | Q34: =IFERROR(VLOOKUP(A34,Ref_Data!$A:$C,3,0),"Unknown") -> Sub-Saharan Africa | R34: =IF(D34="","No Data",IF(D34>=95,"Universal Access",IF(D34>=80,"High Access",IF(D34>=50,"Moderate Access",IF(D34>=20,"Low Access","Critical"))))) -> Low Access | S34: =IF(D34="","",D34-AVERAGEIF($C:$C,C34,$D:$D)) -> -42.294751 | T34: =IF(E34="","",E34-AVERAGEIF($C:$C,C34,$E:$E)) -> 18.393942 | U34: =IF(F34="","",F34-AVERAGEIF($C:$C,C34,$F:$F)) -> -3.6026956 | V34: =IFERROR(IF(D34="","",D34-INDEX($D:$D,MATCH(A34&"-2010",$I:$I,0))),"") -> 6.8 | W34: =IFERROR(IF(F34="","",F34-INDEX($F:$F,MATCH(A34&"-2010",$I:$I,0))),"") -> 0.095497961
A35: AGO | B35: Angola | C35: 2017 | D35: 42.9 | E35: 52.5 | F35: 0.92592191 | G35: 456.69222 | H35: 30234839 | I35: =Master_Data!$A35 & "-" & Master_Data!$C35 -> AGO-2017 | J35: =IF(C35=2010,"",IF(D35="","",IFERROR(D35-INDEX($D:$D,MATCH(A35&"-"&(C35-1),$I:$I,0)),""))) -> 1.1 | K35: =IF(C35=2010,"",IF(E35="","",IFERROR(E35-INDEX($E:$E,MATCH(A35&"-"&(C35-1),$I:$I,0)),""))) -> 4.4 | L35: =IF(C35=2010,"",IF(F35="","",IFERROR(F35-INDEX($F:$F,MATCH(A35&"-"&(C35-1),$I:$I,0)),"" ))) -> -0.14575423 | M35: =IFERROR(F35*H35,"") -> 27995100 | N35: =IF(D35="","",100-D35) -> 57.1 | O35: =IFERROR(F35/G35*1000,"") -> 2.0274528 | P35: =IFERROR(VLOOKUP(A35,Ref_Data!$A:$B,2,0),"Unknown") -> Lower Middle Income | Q35: =IFERROR(VLOOKUP(A35,Ref_Data!$A:$C,3,0),"Unknown") -> Sub-Saharan Africa | R35: =IF(D35="","No Data",IF(D35>=95,"Universal Access",IF(D35>=80,"High Access",IF(D35>=50,"Moderate Access",IF(D35>=20,"Low Access","Critical"))))) -> Low Access | S35: =IF(D35="","",D35-AVERAGEIF($C:$C,C35,$D:$D)) -> -41.953908 | T35: =IF(E35="","",E35-AVERAGEIF($C:$C,C35,$E:$E)) -> 22.958481 | U35: =IF(F35="","",F35-AVERAGEIF($C:$C,C35,$F:$F)) -> -3.7518292 | V35: =IFERROR(IF(D35="","",D35-INDEX($D:$D,MATCH(A35&"-2010",$I:$I,0))),"") -> 7.9 | W35: =IFERROR(IF(F35="","",F35-INDEX($F:$F,MATCH(A35&"-2010",$I:$I,0))),"") -> -0.050256271
A36: AGO | B36: Angola | C36: 2018 | D36: 45.3 | E36: 52.5 | F36: 0.82480979 | G36: 405.17975 | H36: 31297155 | I36: =Master_Data!$A36 & "-" & Master_Data!$C36 -> AGO-2018 | J36: =IF(C36=2010,"",IF(D36="","",IFERROR(D36-INDEX($D:$D,MATCH(A36&"-"&(C36-1),$I:$I,0)),""))) -> 2.4 | K36: =IF(C36=2010,"",IF(E36="","",IFERROR(E36-INDEX($E:$E,MATCH(A36&"-"&(C36-1),$I:$I,0)),""))) -> 0 | L36: =IF(C36=2010,"",IF(F36="","",IFERROR(F36-INDEX($F:$F,MATCH(A36&"-"&(C36-1),$I:$I,0)),"" ))) -> -0.10111212 | M36: =IFERROR(F36*H36,"") -> 25814200 | N36: =IF(D36="","",100-D36) -> 54.7 | O36: =IFERROR(F36/G36*1000,"") -> 2.0356639 | P36: =IFERROR(VLOOKUP(A36,Ref_Data!$A:$B,2,0),"Unknown") -> Lower Middle Income | Q36: =IFERROR(VLOOKUP(A36,Ref_Data!$A:$C,3,0),"Unknown") -> Sub-Saharan Africa | R36: =IF(D36="","No Data",IF(D36>=95,"Universal Access",IF(D36>=80,"High Access",IF(D36>=50,"Moderate Access",IF(D36>=20,"Low Access","Critical"))))) -> Low Access | S36: =IF(D36="","",D36-AVERAGEIF($C:$C,C36,$D:$D)) -> -40.183801 | T36: =IF(E36="","",E36-AVERAGEIF($C:$C,C36,$E:$E)) -> 22.93697 | U36: =IF(F36="","",F36-AVERAGEIF($C:$C,C36,$F:$F)) -> -3.8860592 | V36: =IFERROR(IF(D36="","",D36-INDEX($D:$D,MATCH(A36&"-2010",$I:$I,0))),"") -> 10.3 | W36: =IFERROR(IF(F36="","",F36-INDEX($F:$F,MATCH(A36&"-2010",$I:$I,0))),"") -> -0.15136839
A37: AGO | B37: Angola | C37: 2019 | D37: 45.6 | E37: 51 | F37: 0.83384627 | G37: 416.99651 | H37: 32375632 | I37: =Master_Data!$A37 & "-" & Master_Data!$C37 -> AGO-2019 | J37: =IF(C37=2010,"",IF(D37="","",IFERROR(D37-INDEX($D:$D,MATCH(A37&"-"&(C37-1),$I:$I,0)),""))) -> 0.3 | K37: =IF(C37=2010,"",IF(E37="","",IFERROR(E37-INDEX($E:$E,MATCH(A37&"-"&(C37-1),$I:$I,0)),""))) -> -1.5 | L37: =IF(C37=2010,"",IF(F37="","",IFERROR(F37-INDEX($F:$F,MATCH(A37&"-"&(C37-1),$I:$I,0)),"" ))) -> 0.009036476 | M37: =IFERROR(F37*H37,"") -> 26996300 | N37: =IF(D37="","",100-D37) -> 54.4 | O37: =IFERROR(F37/G37*1000,"") -> 1.9996481 | P37: =IFERROR(VLOOKUP(A37,Ref_Data!$A:$B,2,0),"Unknown") -> Lower Middle Income | Q37: =IFERROR(VLOOKUP(A37,Ref_Data!$A:$C,3,0),"Unknown") -> Sub-Saharan Africa | R37: =IF(D37="","No Data",IF(D37>=95,"Universal Access",IF(D37>=80,"High Access",IF(D37>=50,"Moderate Access",IF(D37>=20,"Low Access","Critical"))))) -> Low Access | S37: =IF(D37="","",D37-AVERAGEIF($C:$C,C37,$D:$D)) -> -40.441377 | T37: =IF(E37="","",E37-AVERAGEIF($C:$C,C37,$E:$E)) -> 21.537809 | U37: =IF(F37="","",F37-AVERAGEIF($C:$C,C37,$F:$F)) -> -3.849555 | V37: =IFERROR(IF(D37="","",D37-INDEX($D:$D,MATCH(A37&"-2010",$I:$I,0))),"") -> 10.6 | W37: =IFERROR(IF(F37="","",F37-INDEX($F:$F,MATCH(A37&"-2010",$I:$I,0))),"") -> -0.14233191
A38: AGO | B38: Angola | C38: 2020 | D38: 47 | E38: 60.1 | F38: 0.61397025 | G38: 397.63319 | H38: 33451132 | I38: =Master_Data!$A38 & "-" & Master_Data!$C38 -> AGO-2020 | J38: =IF(C38=2010,"",IF(D38="","",IFERROR(D38-INDEX($D:$D,MATCH(A38&"-"&(C38-1),$I:$I,0)),""))) -> 1.4 | K38: =IF(C38=2010,"",IF(E38="","",IFERROR(E38-INDEX($E:$E,MATCH(A38&"-"&(C38-1),$I:$I,0)),""))) -> 9.1 | L38: =IF(C38=2010,"",IF(F38="","",IFERROR(F38-INDEX($F:$F,MATCH(A38&"-"&(C38-1),$I:$I,0)),"" ))) -> -0.21987602 | M38: =IFERROR(F38*H38,"") -> 20538000 | N38: =IF(D38="","",100-D38) -> 53 | O38: =IFERROR(F38/G38*1000,"") -> 1.5440619 | P38: =IFERROR(VLOOKUP(A38,Ref_Data!$A:$B,2,0),"Unknown") -> Lower Middle Income | Q38: =IFERROR(VLOOKUP(A38,Ref_Data!$A:$C,3,0),"Unknown") -> Sub-Saharan Africa | R38: =IF(D38="","No Data",IF(D38>=95,"Universal Access",IF(D38>=80,"High Access",IF(D38>=50,"Moderate Access",IF(D38>=20,"Low Access","Critical"))))) -> Low Access | S38: =IF(D38="","",D38-AVERAGEIF($C:$C,C38,$D:$D)) -> -39.573835 | T38: =IF(E38="","",E38-AVERAGEIF($C:$C,C38,$E:$E)) -> 29.565147 | U38: =IF(F38="","",F38-AVERAGEIF($C:$C,C38,$F:$F)) -> -3.7867774 | V38: =IFERROR(IF(D38="","",D38-INDEX($D:$D,MATCH(A38&"-2010",$I:$I,0))),"") -> 12 | W38: =IFERROR(IF(F38="","",F38-INDEX($F:$F,MATCH(A38&"-2010",$I:$I,0))),"") -> -0.36220793
A39: AGO | B39: Angola | C39: 2021 | D39: 48.2 | E39: 52.9 | F39: 0.74029255 | G39: 418.359 | H39: 34532429 | I39: =Master_Data!$A39 & "-" & Master_Data!$C39 -> AGO-2021 | J39: =IF(C39=2010,"",IF(D39="","",IFERROR(D39-INDEX($D:$D,MATCH(A39&"-"&(C39-1),$I:$I,0)),""))) -> 1.2 | K39: =IF(C39=2010,"",IF(E39="","",IFERROR(E39-INDEX($E:$E,MATCH(A39&"-"&(C39-1),$I:$I,0)),""))) -> -7.2 | L39: =IF(C39=2010,"",IF(F39="","",IFERROR(F39-INDEX($F:$F,MATCH(A39&"-"&(C39-1),$I:$I,0)),"" ))) -> 0.1263223 | M39: =IFERROR(F39*H39,"") -> 25564100 | N39: =IF(D39="","",100-D39) -> 51.8 | O39: =IFERROR(F39/G39*1000,"") -> 1.7695151 | P39: =IFERROR(VLOOKUP(A39,Ref_Data!$A:$B,2,0),"Unknown") -> Lower Middle Income | Q39: =IFERROR(VLOOKUP(A39,Ref_Data!$A:$C,3,0),"Unknown") -> Sub-Saharan Africa | R39: =IF(D39="","No Data",IF(D39>=95,"Universal Access",IF(D39>=80,"High Access",IF(D39>=50,"Moderate Access",IF(D39>=20,"Low Access","Critical"))))) -> Low Access | S39: =IF(D39="","",D39-AVERAGEIF($C:$C,C39,$D:$D)) -> -38.925169 | T39: =IF(E39="","",E39-AVERAGEIF($C:$C,C39,$E:$E)) -> 23.296618 | U39: =IF(F39="","",F39-AVERAGEIF($C:$C,C39,$F:$F)) -> -3.8404418 | V39: =IFERROR(IF(D39="","",D39-INDEX($D:$D,MATCH(A39&"-2010",$I:$I,0))),"") -> 13.2 | W39: =IFERROR(IF(F39="","",F39-INDEX($F:$F,MATCH(A39&"-2010",$I:$I,0))),"") -> -0.23588563
A40: AGO | B40: Angola | C40: 2022 | D40: 48.5 | F40: 0.74881095 | G40: 423.12252 | H40: 35635029 | I40: =Master_Data!$A40 & "-" & Master_Data!$C40 -> AGO-2022 | J40: =IF(C40=2010,"",IF(D40="","",IFERROR(D40-INDEX($D:$D,MATCH(A40&"-"&(C40-1),$I:$I,0)),""))) -> 0.3 | K40: =IF(C40=2010,"",IF(E40="","",IFERROR(E40-INDEX($E:$E,MATCH(A40&"-"&(C40-1),$I:$I,0)),""))) | L40: =IF(C40=2010,"",IF(F40="","",IFERROR(F40-INDEX($F:$F,MATCH(A40&"-"&(C40-1),$I:$I,0)),"" ))) -> 0.0085184 | M40: =IFERROR(F40*H40,"") -> 26683900 | N40: =IF(D40="","",100-D40) -> 51.5 | O40: =IFERROR(F40/G40*1000,"") -> 1.7697261 | P40: =IFERROR(VLOOKUP(A40,Ref_Data!$A:$B,2,0),"Unknown") -> Lower Middle Income | Q40: =IFERROR(VLOOKUP(A40,Ref_Data!$A:$C,3,0),"Unknown") -> Sub-Saharan Africa | R40: =IF(D40="","No Data",IF(D40>=95,"Universal Access",IF(D40>=80,"High Access",IF(D40>=50,"Moderate Access",IF(D40>=20,"Low Access","Critical"))))) -> Low Access | S40: =IF(D40="","",D40-AVERAGEIF($C:$C,C40,$D:$D)) -> -38.914054 | T40: =IF(E40="","",E40-AVERAGEIF($C:$C,C40,$E:$E)) | U40: =IF(F40="","",F40-AVERAGEIF($C:$C,C40,$F:$F)) -> -3.8019901 | V40: =IFERROR(IF(D40="","",D40-INDEX($D:$D,MATCH(A40&"-2010",$I:$I,0))),"") -> 13.5 | W40: =IFERROR(IF(F40="","",F40-INDEX($F:$F,MATCH(A40&"-2010",$I:$I,0))),"") -> -0.22736723
A41: ALB | B41: Albania | C41: 2010 | D41: 99.6 | E41: 37 | F41: 1.5677882 | G41: 731.0534 | H41: 2913021 | I41: =Master_Data!$A41 & "-" & Master_Data!$C41 -> ALB-2010 | J41: =IF(C41=2010,"",IF(D41="","",IFERROR(D41-INDEX($D:$D,MATCH(A41&"-"&(C41-1),$I:$I,0)),""))) | K41: =IF(C41=2010,"",IF(E41="","",IFERROR(E41-INDEX($E:$E,MATCH(A41&"-"&(C41-1),$I:$I,0)),""))) | L41: =IF(C41=2010,"",IF(F41="","",IFERROR(F41-INDEX($F:$F,MATCH(A41&"-"&(C41-1),$I:$I,0)),"" ))) | M41: =IFERROR(F41*H41,"") -> 4567000 | N41: =IF(D41="","",100-D41) -> 0.4 | O41: =IFERROR(F41/G41*1000,"") -> 2.1445605 | P41: =IFERROR(VLOOKUP(A41,Ref_Data!$A:$B,2,0),"Unknown") -> Upper Middle Income | Q41: =IFERROR(VLOOKUP(A41,Ref_Data!$A:$C,3,0),"Unknown") -> Europe & Central Asia | R41: =IF(D41="","No Data",IF(D41>=95,"Universal Access",IF(D41>=80,"High Access",IF(D41>=50,"Moderate Access",IF(D41>=20,"Low Access","Critical"))))) -> Universal Access | S41: =IF(D41="","",D41-AVERAGEIF($C:$C,C41,$D:$D)) -> 19.975343 | T41: =IF(E41="","",E41-AVERAGEIF($C:$C,C41,$E:$E)) -> 6.5873351 | U41: =IF(F41="","",F41-AVERAGEIF($C:$C,C41,$F:$F)) -> -3.530271 | V41: =IFERROR(IF(D41="","",D41-INDEX($D:$D,MATCH(A41&"-2010",$I:$I,0))),"") -> 0 | W41: =IFERROR(IF(F41="","",F41-INDEX($F:$F,MATCH(A41&"-2010",$I:$I,0))),"") -> 0
A42: ALB | B42: Albania | C42: 2011 | D42: 99.7 | E42: 35.8 | F42: 1.7212958 | G42: 766.89462 | H42: 2905195 | I42: =Master_Data!$A42 & "-" & Master_Data!$C42 -> ALB-2011 | J42: =IF(C42=2010,"",IF(D42="","",IFERROR(D42-INDEX($D:$D,MATCH(A42&"-"&(C42-1),$I:$I,0)),""))) -> 0.1 | K42: =IF(C42=2010,"",IF(E42="","",IFERROR(E42-INDEX($E:$E,MATCH(A42&"-"&(C42-1),$I:$I,0)),""))) -> -1.2 | L42: =IF(C42=2010,"",IF(F42="","",IFERROR(F42-INDEX($F:$F,MATCH(A42&"-"&(C42-1),$I:$I,0)),"" ))) -> 0.1535076 | M42: =IFERROR(F42*H42,"") -> 5000700 | N42: =IF(D42="","",100-D42) -> 0.3 | O42: =IFERROR(F42/G42*1000,"") -> 2.2445011 | P42: =IFERROR(VLOOKUP(A42,Ref_Data!$A:$B,2,0),"Unknown") -> Upper Middle Income | Q42: =IFERROR(VLOOKUP(A42,Ref_Data!$A:$C,3,0),"Unknown") -> Europe & Central Asia | R42: =IF(D42="","No Data",IF(D42>=95,"Universal Access",IF(D42>=80,"High Access",IF(D42>=50,"Moderate Access",IF(D42>=20,"Low Access","Critical"))))) -> Universal Access | S42: =IF(D42="","",D42-AVERAGEIF($C:$C,C42,$D:$D)) -> 19.284673 | T42: =IF(E42="","",E42-AVERAGEIF($C:$C,C42,$E:$E)) -> 5.6026297 | U42: =IF(F42="","",F42-AVERAGEIF($C:$C,C42,$F:$F)) -> -3.4052376 | V42: =IFERROR(IF(D42="","",D42-INDEX($D:$D,MATCH(A42&"-2010",$I:$I,0))),"") -> 0.1 | W42: =IFERROR(IF(F42="","",F42-INDEX($F:$F,MATCH(A42&"-2010",$I:$I,0))),"") -> 0.1535076
A43: ALB | B43: Albania | C43: 2012 | D43: 99.9 | E43: 39.9 | F43: 1.5864954 | G43: 699.4449 | H43: 2860708 | I43: =Master_Data!$A43 & "-" & Master_Data!$C43 -> ALB-2012 | J43: =IF(C43=2010,"",IF(D43="","",IFERROR(D43-INDEX($D:$D,MATCH(A43&"-"&(C43-1),$I:$I,0)),""))) -> 0.2 | K43: =IF(C43=2010,"",IF(E43="","",IFERROR(E43-INDEX($E:$E,MATCH(A43&"-"&(C43-1),$I:$I,0)),""))) -> 4.1 | L43: =IF(C43=2010,"",IF(F43="","",IFERROR(F43-INDEX($F:$F,MATCH(A43&"-"&(C43-1),$I:$I,0)),"" ))) -> -0.13480045 | M43: =IFERROR(F43*H43,"") -> 4538500 | N43: =IF(D43="","",100-D43) -> 0.1 | O43: =IFERROR(F43/G43*1000,"") -> 2.2682207 | P43: =IFERROR(VLOOKUP(A43,Ref_Data!$A:$B,2,0),"Unknown") -> Upper Middle Income | Q43: =IFERROR(VLOOKUP(A43,Ref_Data!$A:$C,3,0),"Unknown") -> Europe & Central Asia | R43: =IF(D43="","No Data",IF(D43>=95,"Universal Access",IF(D43>=80,"High Access",IF(D43>=50,"Moderate Access",IF(D43>=20,"Low Access","Critical"))))) -> Universal Access | S43: =IF(D43="","",D43-AVERAGEIF($C:$C,C43,$D:$D)) -> 18.779195 | T43: =IF(E43="","",E43-AVERAGEIF($C:$C,C43,$E:$E)) -> 9.7928705 | U43: =IF(F43="","",F43-AVERAGEIF($C:$C,C43,$F:$F)) -> -3.8190087 | V43: =IFERROR(IF(D43="","",D43-INDEX($D:$D,MATCH(A43&"-2010",$I:$I,0))),"") -> 0.3 | W43: =IFERROR(IF(F43="","",F43-INDEX($F:$F,MATCH(A43&"-2010",$I:$I,0))),"") -> 0.018707154
A44: ALB | B44: Albania | C44: 2013 | D44: 99.9 | E44: 41.1 | F44: 1.6934561 | G44: 826.01838 | H44: 2816902 | I44: =Master_Data!$A44 & "-" & Master_Data!$C44 -> ALB-2013 | J44: =IF(C44=2010,"",IF(D44="","",IFERROR(D44-INDEX($D:$D,MATCH(A44&"-"&(C44-1),$I:$I,0)),""))) -> 0 | K44: =IF(C44=2010,"",IF(E44="","",IFERROR(E44-INDEX($E:$E,MATCH(A44&"-"&(C44-1),$I:$I,0)),""))) -> 1.2 | L44: =IF(C44=2010,"",IF(F44="","",IFERROR(F44-INDEX($F:$F,MATCH(A44&"-"&(C44-1),$I:$I,0)),"" ))) -> 0.10696077 | M44: =IFERROR(F44*H44,"") -> 4770300 | N44: =IF(D44="","",100-D44) -> 0.1 | O44: =IFERROR(F44/G44*1000,"") -> 2.0501434 | P44: =IFERROR(VLOOKUP(A44,Ref_Data!$A:$B,2,0),"Unknown") -> Upper Middle Income | Q44: =IFERROR(VLOOKUP(A44,Ref_Data!$A:$C,3,0),"Unknown") -> Europe & Central Asia | R44: =IF(D44="","No Data",IF(D44>=95,"Universal Access",IF(D44>=80,"High Access",IF(D44>=50,"Moderate Access",IF(D44>=20,"Low Access","Critical"))))) -> Universal Access | S44: =IF(D44="","",D44-AVERAGEIF($C:$C,C44,$D:$D)) -> 18.187462 | T44: =IF(E44="","",E44-AVERAGEIF($C:$C,C44,$E:$E)) -> 10.79836 | U44: =IF(F44="","",F44-AVERAGEIF($C:$C,C44,$F:$F)) -> -3.2749143 | V44: =IFERROR(IF(D44="","",D44-INDEX($D:$D,MATCH(A44&"-2010",$I:$I,0))),"") -> 0.3 | W44: =IFERROR(IF(F44="","",F44-INDEX($F:$F,MATCH(A44&"-2010",$I:$I,0))),"") -> 0.12566793
A45: ALB | B45: Albania | C45: 2014 | D45: 100 | E45: 38.6 | F45: 1.8394479 | G45: 844.59008 | H45: 2773767 | I45: =Master_Data!$A45 & "-" & Master_Data!$C45 -> ALB-2014 | J45: =IF(C45=2010,"",IF(D45="","",IFERROR(D45-INDEX($D:$D,MATCH(A45&"-"&(C45-1),$I:$I,0)),""))) -> 0.1 | K45: =IF(C45=2010,"",IF(E45="","",IFERROR(E45-INDEX($E:$E,MATCH(A45&"-"&(C45-1),$I:$I,0)),""))) -> -2.5 | L45: =IF(C45=2010,"",IF(F45="","",IFERROR(F45-INDEX($F:$F,MATCH(A45&"-"&(C45-1),$I:$I,0)),"" ))) -> 0.1459918 | M45: =IFERROR(F45*H45,"") -> 5102200 | N45: =IF(D45="","",100-D45) -> 0 | O45: =IFERROR(F45/G45*1000,"") -> 2.177918 | P45: =IFERROR(VLOOKUP(A45,Ref_Data!$A:$B,2,0),"Unknown") -> Upper Middle Income | Q45: =IFERROR(VLOOKUP(A45,Ref_Data!$A:$C,3,0),"Unknown") -> Europe & Central Asia | R45: =IF(D45="","No Data",IF(D45>=95,"Universal Access",IF(D45>=80,"High Access",IF(D45>=50,"Moderate Access",IF(D45>=20,"Low Access","Critical"))))) -> Universal Access | S45: =IF(D45="","",D45-AVERAGEIF($C:$C,C45,$D:$D)) -> 17.559097 | T45: =IF(E45="","",E45-AVERAGEIF($C:$C,C45,$E:$E)) -> 8.4882734 | U45: =IF(F45="","",F45-AVERAGEIF($C:$C,C45,$F:$F)) -> -2.951839 | V45: =IFERROR(IF(D45="","",D45-INDEX($D:$D,MATCH(A45&"-2010",$I:$I,0))),"") -> 0.4 | W45: =IFERROR(IF(F45="","",F45-INDEX($F:$F,MATCH(A45&"-2010",$I:$I,0))),"") -> 0.27165973
A46: ALB | B46: Albania | C46: 2015 | D46: 100 | E46: 38.5 | F46: 1.7850886 | G46: 803.98745 | H46: 2731293 | I46: =Master_Data!$A46 & "-" & Master_Data!$C46 -> ALB-2015 | J46: =IF(C46=2010,"",IF(D46="","",IFERROR(D46-INDEX($D:$D,MATCH(A46&"-"&(C46-1),$I:$I,0)),""))) -> 0 | K46: =IF(C46=2010,"",IF(E46="","",IFERROR(E46-INDEX($E:$E,MATCH(A46&"-"&(C46-1),$I:$I,0)),""))) -> -0.1 | L46: =IF(C46=2010,"",IF(F46="","",IFERROR(F46-INDEX($F:$F,MATCH(A46&"-"&(C46-1),$I:$I,0)),"" ))) -> -0.054359341 | M46: =IFERROR(F46*H46,"") -> 4875600 | N46: =IF(D46="","",100-D46) -> 0 | O46: =IFERROR(F46/G46*1000,"") -> 2.2202941 | P46: =IFERROR(VLOOKUP(A46,Ref_Data!$A:$B,2,0),"Unknown") -> Upper Middle Income | Q46: =IFERROR(VLOOKUP(A46,Ref_Data!$A:$C,3,0),"Unknown") -> Europe & Central Asia | R46: =IF(D46="","No Data",IF(D46>=95,"Universal Access",IF(D46>=80,"High Access",IF(D46>=50,"Moderate Access",IF(D46>=20,"Low Access","Critical"))))) -> Universal Access | S46: =IF(D46="","",D46-AVERAGEIF($C:$C,C46,$D:$D)) -> 16.984761 | T46: =IF(E46="","",E46-AVERAGEIF($C:$C,C46,$E:$E)) -> 8.5848428 | U46: =IF(F46="","",F46-AVERAGEIF($C:$C,C46,$F:$F)) -> -2.9243528 | V46: =IFERROR(IF(D46="","",D46-INDEX($D:$D,MATCH(A46&"-2010",$I:$I,0))),"") -> 0.4 | W46: =IFERROR(IF(F46="","",F46-INDEX($F:$F,MATCH(A46&"-2010",$I:$I,0))),"") -> 0.21730038
A47: ALB | B47: Albania | C47: 2016 | D47: 99.9 | E47: 39.4 | F47: 1.6873963 | G47: 840.61936 | H47: 2689469 | I47: =Master_Data!$A47 & "-" & Master_Data!$C47 -> ALB-2016 | J47: =IF(C47=2010,"",IF(D47="","",IFERROR(D47-INDEX($D:$D,MATCH(A47&"-"&(C47-1),$I:$I,0)),""))) -> -0.1 | K47: =IF(C47=2010,"",IF(E47="","",IFERROR(E47-INDEX($E:$E,MATCH(A47&"-"&(C47-1),$I:$I,0)),""))) -> 0.9 | L47: =IF(C47=2010,"",IF(F47="","",IFERROR(F47-INDEX($F:$F,MATCH(A47&"-"&(C47-1),$I:$I,0)),"" ))) -> -0.097692316 | M47: =IFERROR(F47*H47,"") -> 4538200 | N47: =IF(D47="","",100-D47) -> 0.1 | O47: =IFERROR(F47/G47*1000,"") -> 2.007325 | P47: =IFERROR(VLOOKUP(A47,Ref_Data!$A:$B,2,0),"Unknown") -> Upper Middle Income | Q47: =IFERROR(VLOOKUP(A47,Ref_Data!$A:$C,3,0),"Unknown") -> Europe & Central Asia | R47: =IF(D47="","No Data",IF(D47>=95,"Universal Access",IF(D47>=80,"High Access",IF(D47>=50,"Moderate Access",IF(D47>=20,"Low Access","Critical"))))) -> Universal Access | S47: =IF(D47="","",D47-AVERAGEIF($C:$C,C47,$D:$D)) -> 15.805249 | T47: =IF(E47="","",E47-AVERAGEIF($C:$C,C47,$E:$E)) -> 9.6939425 | U47: =IF(F47="","",F47-AVERAGEIF($C:$C,C47,$F:$F)) -> -2.9869755 | V47: =IFERROR(IF(D47="","",D47-INDEX($D:$D,MATCH(A47&"-2010",$I:$I,0))),"") -> 0.3 | W47: =IFERROR(IF(F47="","",F47-INDEX($F:$F,MATCH(A47&"-2010",$I:$I,0))),"") -> 0.11960807
A48: ALB | B48: Albania | C48: 2017 | D48: 99.9 | E48: 36.9 | F48: 2.0244422 | G48: 894.4664 | H48: 2648285 | I48: =Master_Data!$A48 & "-" & Master_Data!$C48 -> ALB-2017 | J48: =IF(C48=2010,"",IF(D48="","",IFERROR(D48-INDEX($D:$D,MATCH(A48&"-"&(C48-1),$I:$I,0)),""))) -> 0 | K48: =IF(C48=2010,"",IF(E48="","",IFERROR(E48-INDEX($E:$E,MATCH(A48&"-"&(C48-1),$I:$I,0)),""))) -> -2.5 | L48: =IF(C48=2010,"",IF(F48="","",IFERROR(F48-INDEX($F:$F,MATCH(A48&"-"&(C48-1),$I:$I,0)),"" ))) -> 0.33704595 | M48: =IFERROR(F48*H48,"") -> 5361300 | N48: =IF(D48="","",100-D48) -> 0.1 | O48: =IFERROR(F48/G48*1000,"") -> 2.263296 | P48: =IFERROR(VLOOKUP(A48,Ref_Data!$A:$B,2,0),"Unknown") -> Upper Middle Income | Q48: =IFERROR(VLOOKUP(A48,Ref_Data!$A:$C,3,0),"Unknown") -> Europe & Central Asia | R48: =IF(D48="","No Data",IF(D48>=95,"Universal Access",IF(D48>=80,"High Access",IF(D48>=50,"Moderate Access",IF(D48>=20,"Low Access","Critical"))))) -> Universal Access | S48: =IF(D48="","",D48-AVERAGEIF($C:$C,C48,$D:$D)) -> 15.046092 | T48: =IF(E48="","",E48-AVERAGEIF($C:$C,C48,$E:$E)) -> 7.3584811 | U48: =IF(F48="","",F48-AVERAGEIF($C:$C,C48,$F:$F)) -> -2.6533088 | V48: =IFERROR(IF(D48="","",D48-INDEX($D:$D,MATCH(A48&"-2010",$I:$I,0))),"") -> 0.3 | W48: =IFERROR(IF(F48="","",F48-INDEX($F:$F,MATCH(A48&"-2010",$I:$I,0))),"") -> 0.45665402
